Workbook

Sheet crudos
E1: Alturas
A2: Fecha | B2: Mes | C2: Parcela | D2: Forma de vida | E2: 0 - 0,25 | F2: 0,25 - 0,50 | G2: 0,50 - 0,75 | H2: 0,75 - 1,00 | I2: 1,00 - 1,25 | J2: 1,25 - 1,50 | K2: Quebrados Nuevos
A3: 39427 | B3: Diciembre | C3: 1 | D3: Gramineas | K3: 0
A4: 39427 | B4: Diciembre | C4: 1 | D4: Latifoliadas | E4: 11 | F4: 11
A5: 39427 | B5: Diciembre | C5: 1 | D5: Arbustos
A6: 39427 | B6: Diciembre | C6: 1 | D6: Lianas / Enredaderas | F6: 2 | I6: 1
A7: 39427 | B7: Diciembre | C7: 1 | D7: Arboles | F7: 1 | G7: 2 | H7: 2 | I7: 3 | J7: 7
A8: 39427 | B8: Diciembre | C8: 1 | D8: Helechos
A9: 39427 | B9: Diciembre | C9: 2 | D9: Gramineas | E9: 1 | K9: 0
A10: 39427 | B10: Diciembre | C10: 2 | D10: Latifoliadas | E10: 9
A11: 39427 | B11: Diciembre | C11: 2 | D11: Arbustos | E11: 1
A12: 39427 | B12: Diciembre | C12: 2 | D12: Lianas / Enredaderas | E12: 2 | F12: 1 | G12: 1 | J12: 1
A13: 39427 | B13: Diciembre | C13: 2 | D13: Arboles | I13: 3
A14: 39427 | B14: Diciembre | C14: 2 | D14: Helechos
A15: 39427 | B15: Diciembre | C15: 3 | D15: Gramineas | E15: 1 | F15: 1 | K15: 1
A16: 39427 | B16: Diciembre | C16: 3 | D16: Latifoliadas | E16: 6 | F16: 2
A17: 39427 | B17: Diciembre | C17: 3 | D17: Arbustos
A18: 39427 | B18: Diciembre | C18: 3 | D18: Lianas / Enredaderas | E18: 2 | F18: 3 | I18: 1 | J18: 2
A19: 39427 | B19: Diciembre | C19: 3 | D19: Arboles | F19: 2 | G19: 2 | H19: 1 | I19: 1 | J19: 1
A20: 39427 | B20: Diciembre | C20: 3 | D20: Helechos | E20: 1
A21: 39427 | B21: Diciembre | C21: 4 | D21: Gramineas | K21: 0
A22: 39427 | B22: Diciembre | C22: 4 | D22: Latifoliadas | E22: 2
A23: 39427 | B23: Diciembre | C23: 4 | D23: Arbustos
A24: 39427 | B24: Diciembre | C24: 4 | D24: Lianas / Enredaderas
A25: 39427 | B25: Diciembre | C25: 4 | D25: Arboles | E25: 1 | F25: 2 | G25: 1 | H25: 2 | J25: 4
A26: 39427 | B26: Diciembre | C26: 4 | D26: Helechos
A27: 39427 | B27: Diciembre | C27: 5 | D27: Gramineas | E27: 1 | K27: 1
A28: 39427 | B28: Diciembre | C28: 5 | D28: Latifoliadas | E28: 4
A29: 39427 | B29: Diciembre | C29: 5 | D29: Arbustos | E29: 2 | F29: 2 | G29: 1
A30: 39427 | B30: Diciembre | C30: 5 | D30: Lianas / Enredaderas | E30: 1 | H30: 1 | I30: 1
A31: 39427 | B31: Diciembre | C31: 5 | D31: Arboles | F31: 2 | G31: 2
A32: 39427 | B32: Diciembre | C32: 5 | D32: Helechos | F32: 3
A33: 39427 | B33: Diciembre | C33: 6 | D33: Gramineas | E33: 3 | K33: 0
A34: 39427 | B34: Diciembre | C34: 6 | D34: Latifoliadas | E34: 5
A35: 39427 | B35: Diciembre | C35: 6 | D35: Arbustos | E35: 5 | F35: 2 | G35: 1 | H35: 2
A36: 39427 | B36: Diciembre | C36: 6 | D36: Lianas / Enredaderas
A37: 39427 | B37: Diciembre | C37: 6 | D37: Arboles
A38: 39427 | B38: Diciembre | C38: 6 | D38: Helechos
A39: 39428 | B39: Diciembre | C39: 7 | D39: Gramineas | E39: 3 | K39: 0
A40: 39428 | B40: Diciembre | C40: 7 | D40: Latifoliadas | E40: 4
...

Sheet Tablas dinámicas probando
A1: Mes | B1: Promedio de Quebrados Nuevos | O1: Quiebres | P1: Meses | Q1: 0 - 0,25 | R1: 0,25 - 0,50 | S1: 0,50 - 0,75 | T1: 0,75 - 1,00 | U1: 1,00 - 1,25 | V1: 1,25 - 1,50 | W1: Sumatoria | X1: Cober. total | Y1: Quiebres | Z1: Peso de frutos | AA1: Meses | AB1: Cober. 0 - 0,5 m | AC1: Cober 0,5 - 1 m | AD1: Cober 1 - 1,5 m | AE1: Suma de quiebres
A2: Febrero | B2: 0.1 | O2: 0.1 | P2: Febrero | Q2: 9.037037 | R2: 3.3928571 | S2: 2.5294118 | T2: 2 | U2: 2.9333333 | V2: 3.6363636 | W2: =SUM(Q2:V2) -> 23.529003 | X2: =W2/6 -> 3.9215005 | Y2: 0.1 | Z2: 8.77 | AA2: Feb | AB2: =Q2+R2/2 -> 10.733466 | AC2: =T2+S2/2 -> 3.2647059 | AD2: =U2+V2/2 -> 4.7515152 | AE2: 1
A3: Abril | B3: 0.5 | O3: 0.5 | P3: Abril | Q3: 6.7931034 | R3: 2.1538462 | S3: 3.1666667 | T3: 2.8 | U3: 2.7 | V3: 4.1428571 | W3: =SUM(Q3:V3) -> 21.756473 | X3: =W3/6 -> 3.6260789 | Y3: 0.5 | Z3: 1.1 | AA3: Abr | AB3: =Q3+R3/2 -> 7.8700265 | AC3: =T3+S3/2 -> 4.3833333 | AD3: =U3+V3/2 -> 4.7714286 | AE3: 5
A4: Junio | B4: 2.9 | O4: 2.9 | P4: Junio | Q4: 5.3043478 | R4: 2.1333333 | S4: 1.5555556 | T4: 2.6 | U4: 2 | V4: 2.8 | W4: =SUM(Q4:V4) -> 16.393237 | X4: =W4/6 -> 2.7322061 | Y4: 2.9 | Z4: 14.78 | AA4: Jun | AB4: =Q4+R4/2 -> 6.3710145 | AC4: =T4+S4/2 -> 3.3777778 | AD4: =U4+V4/2 -> 3.4 | AE4: 29
A5: Agosto | B5: 1.9 | O5: 1.9 | P5: Agosto | Q5: 2.4 | R5: 1.3333333 | S5: 1.625 | T5: 2 | U5: 1.2857143 | V5: 2.1428571 | W5: =SUM(Q5:V5) -> 10.786905 | X5: =W5/6 -> 1.7978175 | Y5: 1.9 | Z5: 30.32 | AA5: Ago | AB5: =Q5+R5/2 -> 3.0666667 | AC5: =T5+S5/2 -> 2.8125 | AD5: =U5+V5/2 -> 2.3571429 | AE5: 19
A6: Octubre | B6: 1.8 | O6: 1.8 | P6: Octubre | Q6: 2.6315789 | R6: 1.7142857 | S6: 2.4 | T6: 2.1666667 | U6: 1.6666667 | V6: 1.6 | W6: =SUM(Q6:V6) -> 12.179198 | X6: =W6/6 -> 2.0298663 | Y6: 1.8 | Z6: 32.09 | AA6: Oct | AB6: =Q6+R6/2 -> 3.4887218 | AC6: =T6+S6/2 -> 3.3666667 | AD6: =U6+V6/2 -> 2.4666667 | AE6: 18
A7: Diciembre | B7: 0.2 | O7: 0.2 | P7: Diciembre | Q7: 3.4375 | R7: 2.8947368 | S7: 1.6363636 | T7: 1.875 | U7: 2.25 | V7: 2.7142857 | W7: =SUM(Q7:V7) -> 14.807886 | X7: =W7/6 -> 2.467981 | Y7: 0.2 | Z7: 11.99 | AA7: Dic | AB7: =Q7+R7/2 -> 4.8848684 | AC7: =T7+S7/2 -> 2.6931818 | AD7: =U7+V7/2 -> 3.6071429 | AE7: 2
A8: Total Resultado | B8: 1.2333333
A11: Mes | B11: (vacío) | P11: 0 - 0,25 | Q11: 0,25 - 0,50 | R11: 0,50 - 0,75 | S11: 0,75 - 1,00 | T11: 1,00 - 1,25 | U11: 1,25 - 1,50
A12: Febrero | O12: Feb | P12: 9.037037 | Q12: 3.3928571 | R12: 2.5294118 | S12: 2 | T12: 2.9333333 | U12: 3.6363636
A13: Abril | O13: Abr | P13: 6.7931034 | Q13: 2.1538462 | R13: 3.1666667 | S13: 2.8 | T13: 2.7 | U13: 4.1428571
A14: Junio | O14: Jun | P14: 5.3043478 | Q14: 2.1333333 | R14: 1.5555556 | S14: 2.6 | T14: 2 | U14: 2.8
A15: Agosto | O15: Ago | P15: 2.4 | Q15: 1.3333333 | R15: 1.625 | S15: 2 | T15: 1.2857143 | U15: 2.1428571
A16: Octubre | O16: Oct | P16: 2.6315789 | Q16: 1.7142857 | R16: 2.4 | S16: 2.1666667 | T16: 1.6666667 | U16: 1.6
A17: Diciembre | O17: Dic | P17: 3.4375 | Q17: 2.8947368 | R17: 1.6363636 | S17: 1.875 | T17: 2.25 | U17: 2.7142857
A18: Total Resultado
A22: Mes | B22: Forma de vida | C22: (vacío)
A23: Febrero
B24: Arboles
B25: Arbustos
B26: Gramineas
B27: Helechos
B28: Latifoliadas
B29: Lianas / Enredaderas
A30: Abril
B31: Arboles
B32: Arbustos
B33: Gramineas
B34: Helechos
B35: Latifoliadas
B36: Lianas / Enredaderas
A37: Junio
B38: Arboles
B39: Arbustos
B40: Gramineas
B41: Helechos
B42: Latifoliadas
B43: Lianas / Enredaderas
A44: Agosto
B45: Arboles
...

Sheet Crudos simplificado
E1: Alturas
A2: Fecha | B2: Mes | C2: Parcela | D2: Forma de vida | E2: 0 - 0,5 | F2: 0,5 - 1 | G2: 1 - 1,5 | H2: Quebrados Nuevos | M2: Datos
A3: 39427 | B3: Diciembre | C3: 1 | D3: Gramineas | E3: =crudos!E3+crudos!F3 -> 0 | F3: =crudos!G3+crudos!H3 -> 0 | G3: =crudos!I3+crudos!J3 -> 0 | H3: 0 | K3: Mes | L3: Parcela | M3: Suma de 0 - 0,5 | N3: Suma de 0,5 - 1 | O3: Suma de 1 - 1,5 | P3: Suma de Quebrados Nuevos | Q3: PLANILLA PASADA EN LIMPIO Y ABREVIADA
A4: 39427 | B4: Diciembre | C4: 1 | D4: Latifoliadas | E4: =crudos!E4+crudos!F4 -> 22 | F4: =crudos!G4+crudos!H4 -> 0 | G4: =crudos!I4+crudos!J4 -> 0 | K4: Febrero | M4: 339 | N4: 75 | O4: 84 | P4: 1 | Q4: Mes | R4: Toques 0 - 0,5 m | S4: Toques 0,5 - 1 m | T4: Toques 1 - 1,5 m | U4: Toques totales | V4: Suma de Quebrados Nuevos | W4: Dif (0-0,5m)-Quiebres | X4: Dif (0,5-1m)-Quiebres | Y4: Dif (1-1,5m)-Quiebres | Z4: Dif (0-1,5m)-Quiebres | AB4: Medidas resumen
A5: 39427 | B5: Diciembre | C5: 1 | D5: Arbustos | E5: =crudos!E5+crudos!F5 -> 0 | F5: =crudos!G5+crudos!H5 -> 0 | G5: =crudos!I5+crudos!J5 -> 0 | L5: 1 | M5: 35 | N5: 10 | O5: 11 | P5: 0 | Q5: Feb | R5: 35 | S5: 10 | T5: 11 | U5: =SUM(R5:T5) -> 56 | V5: 0 | W5: =R5-V5 -> 35 | X5: =S5-V5 -> 10 | Y5: =T5-V5 -> 11 | Z5: =U5-V5 -> 56
A6: 39427 | B6: Diciembre | C6: 1 | D6: Lianas / Enredaderas | E6: =crudos!E6+crudos!F6 -> 2 | F6: =crudos!G6+crudos!H6 -> 0 | G6: =crudos!I6+crudos!J6 -> 1 | L6: 2 | M6: 52 | N6: 3 | O6: 1 | P6: 1 | Q6: Feb | R6: 52 | S6: 3 | T6: 1 | U6: =SUM(R6:T6) -> 56 | V6: 1 | W6: =R6-V6 -> 51 | X6: =S6-V6 -> 2 | Y6: =T6-V6 -> 0 | Z6: =U6-V6 -> 55 | AB6: Mes | AC6: Variable | AD6: n | AE6: Media | AF6: D.E. | AG6: E.E. | AH6: Mín | AI6: Máx
A7: 39427 | B7: Diciembre | C7: 1 | D7: Arboles | E7: =crudos!E7+crudos!F7 -> 1 | F7: =crudos!G7+crudos!H7 -> 4 | G7: =crudos!I7+crudos!J7 -> 10 | L7: 3 | M7: 32 | N7: 11 | O7: 4 | P7: 0 | Q7: Feb | R7: 32 | S7: 11 | T7: 4 | U7: =SUM(R7:T7) -> 47 | V7: 0 | W7: =R7-V7 -> 32 | X7: =S7-V7 -> 11 | Y7: =T7-V7 -> 4 | Z7: =U7-V7 -> 47 | AB7: Abr | AC7: Toques 0-0,5m | AD7: 10 | AE7: 25.3 | AF7: 7.5 | AG7: 2.37 | AH7: 11 | AI7: 37
A8: 39427 | B8: Diciembre | C8: 1 | D8: Helechos | E8: =crudos!E8+crudos!F8 -> 0 | F8: =crudos!G8+crudos!H8 -> 0 | G8: =crudos!I8+crudos!J8 -> 0 | L8: 4 | M8: 27 | N8: 7 | O8: 8 | P8: 0 | Q8: Feb | R8: 27 | S8: 7 | T8: 8 | U8: =SUM(R8:T8) -> 42 | V8: 0 | W8: =R8-V8 -> 27 | X8: =S8-V8 -> 7 | Y8: =T8-V8 -> 8 | Z8: =U8-V8 -> 42 | AB8: Abr | AC8: Toques 0,5-1m | AD8: 10 | AE8: 6.6 | AF8: 5.42 | AG8: 1.71 | AH8: 0 | AI8: 19
A9: 39427 | B9: Diciembre | C9: 2 | D9: Gramineas | E9: =crudos!E9+crudos!F9 -> 1 | F9: =crudos!G9+crudos!H9 -> 0 | G9: =crudos!I9+crudos!J9 -> 0 | H9: 0 | L9: 5 | M9: 61 | N9: 3 | O9: 15 | P9: 0 | Q9: Feb | R9: 61 | S9: 3 | T9: 15 | U9: =SUM(R9:T9) -> 79 | V9: 0 | W9: =R9-V9 -> 61 | X9: =S9-V9 -> 3 | Y9: =T9-V9 -> 15 | Z9: =U9-V9 -> 79 | AB9: Abr | AC9: Toques 1-1,5m | AD9: 10 | AE9: 5.6 | AF9: 3.92 | AG9: 1.24 | AH9: 0 | AI9: 12
A10: 39427 | B10: Diciembre | C10: 2 | D10: Latifoliadas | E10: =crudos!E10+crudos!F10 -> 9 | F10: =crudos!G10+crudos!H10 -> 0 | G10: =crudos!I10+crudos!J10 -> 0 | L10: 6 | M10: 20 | N10: 4 | O10: 12 | P10: 0 | Q10: Feb | R10: 20 | S10: 4 | T10: 12 | U10: =SUM(R10:T10) -> 36 | V10: 0 | W10: =R10-V10 -> 20 | X10: =S10-V10 -> 4 | Y10: =T10-V10 -> 12 | Z10: =U10-V10 -> 36 | AB10: Abr | AC10: Toques totales | AD10: 10 | AE10: 37.5 | AF10: 8.76 | AG10: 2.77 | AH10: 25 | AI10: 52
A11: 39427 | B11: Diciembre | C11: 2 | D11: Arbustos | E11: =crudos!E11+crudos!F11 -> 1 | F11: =crudos!G11+crudos!H11 -> 0 | G11: =crudos!I11+crudos!J11 -> 0 | L11: 7 | M11: 30 | N11: 12 | O11: 18 | P11: 0 | Q11: Feb | R11: 30 | S11: 12 | T11: 18 | U11: =SUM(R11:T11) -> 60 | V11: 0 | W11: =R11-V11 -> 30 | X11: =S11-V11 -> 12 | Y11: =T11-V11 -> 18 | Z11: =U11-V11 -> 60 | AB11: Abr | AC11: Quiebres nuevos | AD11: 10 | AE11: 0.5 | AF11: 0.85 | AG11: 0.27 | AH11: 0 | AI11: 2
A12: 39427 | B12: Diciembre | C12: 2 | D12: Lianas / Enredaderas | E12: =crudos!E12+crudos!F12 -> 3 | F12: =crudos!G12+crudos!H12 -> 1 | G12: =crudos!I12+crudos!J12 -> 1 | L12: 8 | M12: 41 | N12: 9 | O12: 8 | P12: 0 | Q12: Feb | R12: 41 | S12: 9 | T12: 8 | U12: =SUM(R12:T12) -> 58 | V12: 0 | W12: =R12-V12 -> 41 | X12: =S12-V12 -> 9 | Y12: =T12-V12 -> 8 | Z12: =U12-V12 -> 58 | AB12: Abr | AC12: (0-0,5m)-Q | AD12: 10 | AE12: 24.8 | AF12: 7.77 | AG12: 2.46 | AH12: 11 | AI12: 37
A13: 39427 | B13: Diciembre | C13: 2 | D13: Arboles | E13: =crudos!E13+crudos!F13 -> 0 | F13: =crudos!G13+crudos!H13 -> 0 | G13: =crudos!I13+crudos!J13 -> 3 | L13: 9 | M13: 17 | N13: 5 | O13: 3 | P13: 0 | Q13: Feb | R13: 17 | S13: 5 | T13: 3 | U13: =SUM(R13:T13) -> 25 | V13: 0 | W13: =R13-V13 -> 17 | X13: =S13-V13 -> 5 | Y13: =T13-V13 -> 3 | Z13: =U13-V13 -> 25 | AB13: Abr | AC13: (0,5-1m)-Q | AD13: 10 | AE13: 6.1 | AF13: 5.47 | AG13: 1.73 | AH13: -1 | AI13: 19
A14: 39427 | B14: Diciembre | C14: 2 | D14: Helechos | E14: =crudos!E14+crudos!F14 -> 0 | F14: =crudos!G14+crudos!H14 -> 0 | G14: =crudos!I14+crudos!J14 -> 0 | L14: 10 | M14: 24 | N14: 11 | O14: 4 | P14: 0 | Q14: Feb | R14: 24 | S14: 11 | T14: 4 | U14: =SUM(R14:T14) -> 39 | V14: 0 | W14: =R14-V14 -> 24 | X14: =S14-V14 -> 11 | Y14: =T14-V14 -> 4 | Z14: =U14-V14 -> 39 | AB14: Abr | AC14: (1-1,5m)-Q | AD14: 10 | AE14: 5.1 | AF14: 3.96 | AG14: 1.25 | AH14: 0 | AI14: 12
A15: 39427 | B15: Diciembre | C15: 3 | D15: Gramineas | E15: =crudos!E15+crudos!F15 -> 2 | F15: =crudos!G15+crudos!H15 -> 0 | G15: =crudos!I15+crudos!J15 -> 0 | H15: 1 | K15: Abril | M15: 253 | N15: 66 | O15: 56 | P15: 5 | Q15: Abr | R15: 29 | S15: 4 | T15: 0 | U15: =SUM(R15:T15) -> 33 | V15: 0 | W15: =R15-V15 -> 29 | X15: =S15-V15 -> 4 | Y15: =T15-V15 -> 0 | Z15: =U15-V15 -> 33 | AB15: Abr | AC15: Totales-Q | AD15: 10 | AE15: 37 | AF15: 8.96 | AG15: 2.83 | AH15: 24 | AI15: 52
A16: 39427 | B16: Diciembre | C16: 3 | D16: Latifoliadas | E16: =crudos!E16+crudos!F16 -> 8 | F16: =crudos!G16+crudos!H16 -> 0 | G16: =crudos!I16+crudos!J16 -> 0 | L16: 1 | M16: 29 | N16: 4 | O16: 0 | P16: 0 | Q16: Abr | R16: 17 | S16: 8 | T16: 4 | U16: =SUM(R16:T16) -> 29 | V16: 2 | W16: =R16-V16 -> 15 | X16: =S16-V16 -> 6 | Y16: =T16-V16 -> 2 | Z16: =U16-V16 -> 27 | AB16: Ago | AC16: Toques 0-0,5m | AD16: 10 | AE16: 1.6 | AF16: 2.07 | AG16: 0.65 | AH16: 0 | AI16: 5
A17: 39427 | B17: Diciembre | C17: 3 | D17: Arbustos | E17: =crudos!E17+crudos!F17 -> 0 | F17: =crudos!G17+crudos!H17 -> 0 | G17: =crudos!I17+crudos!J17 -> 0 | L17: 2 | M17: 17 | N17: 8 | O17: 4 | P17: 2 | Q17: Abr | R17: 28 | S17: 7 | T17: 9 | U17: =SUM(R17:T17) -> 44 | V17: 0 | W17: =R17-V17 -> 28 | X17: =S17-V17 -> 7 | Y17: =T17-V17 -> 9 | Z17: =U17-V17 -> 44 | AB17: Ago | AC17: Toques 0,5-1m | AD17: 10 | AE17: 2.7 | AF17: 2.06 | AG17: 0.65 | AH17: 0 | AI17: 7
A18: 39427 | B18: Diciembre | C18: 3 | D18: Lianas / Enredaderas | E18: =crudos!E18+crudos!F18 -> 5 | F18: =crudos!G18+crudos!H18 -> 0 | G18: =crudos!I18+crudos!J18 -> 3 | L18: 3 | M18: 28 | N18: 7 | O18: 9 | P18: 0 | Q18: Abr | R18: 28 | S18: 2 | T18: 1 | U18: =SUM(R18:T18) -> 31 | V18: 0 | W18: =R18-V18 -> 28 | X18: =S18-V18 -> 2 | Y18: =T18-V18 -> 1 | Z18: =U18-V18 -> 31 | AB18: Ago | AC18: Toques 1-1,5m | AD18: 10 | AE18: 2.4 | AF18: 2.37 | AG18: 0.75 | AH18: 0 | AI18: 7
A19: 39427 | B19: Diciembre | C19: 3 | D19: Arboles | E19: =crudos!E19+crudos!F19 -> 2 | F19: =crudos!G19+crudos!H19 -> 3 | G19: =crudos!I19+crudos!J19 -> 2 | L19: 4 | M19: 28 | N19: 2 | O19: 1 | P19: 0 | Q19: Abr | R19: 26 | S19: 4 | T19: 2 | U19: =SUM(R19:T19) -> 32 | V19: 0 | W19: =R19-V19 -> 26 | X19: =S19-V19 -> 4 | Y19: =T19-V19 -> 2 | Z19: =U19-V19 -> 32 | AB19: Ago | AC19: Toques totales | AD19: 10 | AE19: 6.7 | AF19: 4.79 | AG19: 1.51 | AH19: 0 | AI19: 14
A20: 39427 | B20: Diciembre | C20: 3 | D20: Helechos | E20: =crudos!E20+crudos!F20 -> 1 | F20: =crudos!G20+crudos!H20 -> 0 | G20: =crudos!I20+crudos!J20 -> 0 | L20: 5 | M20: 26 | N20: 4 | O20: 2 | P20: 0 | Q20: Abr | R20: 11 | S20: 19 | T20: 9 | U20: =SUM(R20:T20) -> 39 | V20: 0 | W20: =R20-V20 -> 11 | X20: =S20-V20 -> 19 | Y20: =T20-V20 -> 9 | Z20: =U20-V20 -> 39 | AB20: Ago | AC20: Quiebres nuevos | AD20: 10 | AE20: 1.9 | AF20: 2.23 | AG20: 0.71 | AH20: 0 | AI20: 7
A21: 39427 | B21: Diciembre | C21: 4 | D21: Gramineas | E21: =crudos!E21+crudos!F21 -> 0 | F21: =crudos!G21+crudos!H21 -> 0 | G21: =crudos!I21+crudos!J21 -> 0 | H21: 0 | L21: 6 | M21: 11 | N21: 19 | O21: 9 | P21: 0 | Q21: Abr | R21: 29 | S21: 9 | T21: 8 | U21: =SUM(R21:T21) -> 46 | V21: 2 | W21: =R21-V21 -> 27 | X21: =S21-V21 -> 7 | Y21: =T21-V21 -> 6 | Z21: =U21-V21 -> 44 | AB21: Ago | AC21: (0-0,5m)-Q | AD21: 10 | AE21: -0.3 | AF21: 3.4 | AG21: 1.08 | AH21: -7 | AI21: 5
A22: 39427 | B22: Diciembre | C22: 4 | D22: Latifoliadas | E22: =crudos!E22+crudos!F22 -> 2 | F22: =crudos!G22+crudos!H22 -> 0 | G22: =crudos!I22+crudos!J22 -> 0 | L22: 7 | M22: 29 | N22: 9 | O22: 8 | P22: 2 | Q22: Abr | R22: 19 | S22: 0 | T22: 6 | U22: =SUM(R22:T22) -> 25 | V22: 1 | W22: =R22-V22 -> 18 | X22: =S22-V22 -> -1 | Y22: =T22-V22 -> 5 | Z22: =U22-V22 -> 24 | AB22: Ago | AC22: (0,5-1m)-Q | AD22: 10 | AE22: 0.8 | AF22: 3.74 | AG22: 1.18 | AH22: -7 | AI22: 7
A23: 39427 | B23: Diciembre | C23: 4 | D23: Arbustos | E23: =crudos!E23+crudos!F23 -> 0 | F23: =crudos!G23+crudos!H23 -> 0 | G23: =crudos!I23+crudos!J23 -> 0 | L23: 8 | M23: 19 | N23: 0 | O23: 6 | P23: 1 | Q23: Abr | R23: 37 | S23: 10 | T23: 5 | U23: =SUM(R23:T23) -> 52 | V23: 0 | W23: =R23-V23 -> 37 | X23: =S23-V23 -> 10 | Y23: =T23-V23 -> 5 | Z23: =U23-V23 -> 52 | AB23: Ago | AC23: (1-1,5m)-Q | AD23: 10 | AE23: 0.5 | AF23: 3.92 | AG23: 1.24 | AH23: -7 | AI23: 7
A24: 39427 | B24: Diciembre | C24: 4 | D24: Lianas / Enredaderas | E24: =crudos!E24+crudos!F24 -> 0 | F24: =crudos!G24+crudos!H24 -> 0 | G24: =crudos!I24+crudos!J24 -> 0 | L24: 9 | M24: 37 | N24: 10 | O24: 5 | P24: 0 | Q24: Abr | R24: 29 | S24: 3 | T24: 12 | U24: =SUM(R24:T24) -> 44 | V24: 0 | W24: =R24-V24 -> 29 | X24: =S24-V24 -> 3 | Y24: =T24-V24 -> 12 | Z24: =U24-V24 -> 44 | AB24: Ago | AC24: Totales-Q | AD24: 10 | AE24: 4.8 | AF24: 6.3 | AG24: 1.99 | AH24: -7 | AI24: 14
A25: 39427 | B25: Diciembre | C25: 4 | D25: Arboles | E25: =crudos!E25+crudos!F25 -> 3 | F25: =crudos!G25+crudos!H25 -> 3 | G25: =crudos!I25+crudos!J25 -> 4 | L25: 10 | M25: 29 | N25: 3 | O25: 12 | P25: 0 | Q25: Jun | R25: 9 | S25: 3 | T25: 5 | U25: =SUM(R25:T25) -> 17 | V25: 0 | W25: =R25-V25 -> 9 | X25: =S25-V25 -> 3 | Y25: =T25-V25 -> 5 | Z25: =U25-V25 -> 17 | AB25: Dic | AC25: Toques 0-0,5m | AD25: 10 | AE25: 16.5 | AF25: 8.07 | AG25: 2.55 | AH25: 5 | AI25: 32
A26: 39427 | B26: Diciembre | C26: 4 | D26: Helechos | E26: =crudos!E26+crudos!F26 -> 0 | F26: =crudos!G26+crudos!H26 -> 0 | G26: =crudos!I26+crudos!J26 -> 0 | K26: Junio | M26: 154 | N26: 27 | O26: 34 | P26: 29 | Q26: Jun | R26: 10 | S26: 4 | T26: 3 | U26: =SUM(R26:T26) -> 17 | V26: 0 | W26: =R26-V26 -> 10 | X26: =S26-V26 -> 4 | Y26: =T26-V26 -> 3 | Z26: =U26-V26 -> 17 | AB26: Dic | AC26: Toques 0,5-1m | AD26: 10 | AE26: 3.3 | AF26: 1.49 | AG26: 0.47 | AH26: 1 | AI26: 6
A27: 39427 | B27: Diciembre | C27: 5 | D27: Gramineas | E27: =crudos!E27+crudos!F27 -> 1 | F27: =crudos!G27+crudos!H27 -> 0 | G27: =crudos!I27+crudos!J27 -> 0 | H27: 1 | L27: 1 | M27: 9 | N27: 3 | O27: 5 | P27: 0 | Q27: Jun | R27: 18 | S27: 5 | T27: 4 | U27: =SUM(R27:T27) -> 27 | V27: 0 | W27: =R27-V27 -> 18 | X27: =S27-V27 -> 5 | Y27: =T27-V27 -> 4 | Z27: =U27-V27 -> 27 | AB27: Dic | AC27: Toques 1-1,5m | AD27: 10 | AE27: 3.7 | AF27: 3.2 | AG27: 1.01 | AH27: 0 | AI27: 11
A28: 39427 | B28: Diciembre | C28: 5 | D28: Latifoliadas | E28: =crudos!E28+crudos!F28 -> 4 | F28: =crudos!G28+crudos!H28 -> 0 | G28: =crudos!I28+crudos!J28 -> 0 | L28: 2 | M28: 10 | N28: 4 | O28: 3 | P28: 0 | Q28: Jun | R28: 12 | S28: 0 | T28: 5 | U28: =SUM(R28:T28) -> 17 | V28: 0 | W28: =R28-V28 -> 12 | X28: =S28-V28 -> 0 | Y28: =T28-V28 -> 5 | Z28: =U28-V28 -> 17 | AB28: Dic | AC28: Toques totales | AD28: 10 | AE28: 23.5 | AF28: 10.05 | AG28: 3.18 | AH28: 12 | AI28: 41
A29: 39427 | B29: Diciembre | C29: 5 | D29: Arbustos | E29: =crudos!E29+crudos!F29 -> 4 | F29: =crudos!G29+crudos!H29 -> 1 | G29: =crudos!I29+crudos!J29 -> 0 | L29: 3 | M29: 18 | N29: 5 | O29: 4 | P29: 0 | Q29: Jun | R29: 20 | S29: 5 | T29: 6 | U29: =SUM(R29:T29) -> 31 | V29: 3 | W29: =R29-V29 -> 17 | X29: =S29-V29 -> 2 | Y29: =T29-V29 -> 3 | Z29: =U29-V29 -> 28 | AB29: Dic | AC29: Quiebres nuevos | AD29: 10 | AE29: 0.2 | AF29: 0.42 | AG29: 0.13 | AH29: 0 | AI29: 1
A30: 39427 | B30: Diciembre | C30: 5 | D30: Lianas / Enredaderas | E30: =crudos!E30+crudos!F30 -> 1 | F30: =crudos!G30+crudos!H30 -> 1 | G30: =crudos!I30+crudos!J30 -> 1 | L30: 4 | M30: 12 | N30: 0 | O30: 5 | P30: 0 | Q30: Jun | R30: 16 | S30: 0 | T30: 0 | U30: =SUM(R30:T30) -> 16 | V30: 2 | W30: =R30-V30 -> 14 | X30: =S30-V30 -> -2 | Y30: =T30-V30 -> -2 | Z30: =U30-V30 -> 14 | AB30: Dic | AC30: (0-0,5m)-Q | AD30: 10 | AE30: 16.3 | AF30: 8.08 | AG30: 2.56 | AH30: 5 | AI30: 32
A31: 39427 | B31: Diciembre | C31: 5 | D31: Arboles | E31: =crudos!E31+crudos!F31 -> 2 | F31: =crudos!G31+crudos!H31 -> 2 | G31: =crudos!I31+crudos!J31 -> 0 | L31: 5 | M31: 20 | N31: 5 | O31: 6 | P31: 3 | Q31: Jun | R31: 21 | S31: 5 | T31: 4 | U31: =SUM(R31:T31) -> 30 | V31: 9 | W31: =R31-V31 -> 12 | X31: =S31-V31 -> -4 | Y31: =T31-V31 -> -5 | Z31: =U31-V31 -> 21 | AB31: Dic | AC31: (0,5-1m)-Q | AD31: 10 | AE31: 3.1 | AF31: 1.52 | AG31: 0.48 | AH31: 1 | AI31: 6
A32: 39427 | B32: Diciembre | C32: 5 | D32: Helechos | E32: =crudos!E32+crudos!F32 -> 3 | F32: =crudos!G32+crudos!H32 -> 0 | G32: =crudos!I32+crudos!J32 -> 0 | L32: 6 | M32: 16 | N32: 0 | O32: 0 | P32: 2 | Q32: Jun | R32: 14 | S32: 3 | T32: 5 | U32: =SUM(R32:T32) -> 22 | V32: 14 | W32: =R32-V32 -> 0 | X32: =S32-V32 -> -11 | Y32: =T32-V32 -> -9 | Z32: =U32-V32 -> 8 | AB32: Dic | AC32: (1-1,5m)-Q | AD32: 10 | AE32: 3.5 | AF32: 3.27 | AG32: 1.04 | AH32: 0 | AI32: 11
A33: 39427 | B33: Diciembre | C33: 6 | D33: Gramineas | E33: =crudos!E33+crudos!F33 -> 3 | F33: =crudos!G33+crudos!H33 -> 0 | G33: =crudos!I33+crudos!J33 -> 0 | H33: 0 | L33: 7 | M33: 21 | N33: 5 | O33: 4 | P33: 9 | Q33: Jun | R33: 18 | S33: 0 | T33: 2 | U33: =SUM(R33:T33) -> 20 | V33: 1 | W33: =R33-V33 -> 17 | X33: =S33-V33 -> -1 | Y33: =T33-V33 -> 1 | Z33: =U33-V33 -> 19 | AB33: Dic | AC33: Totales-Q | AD33: 10 | AE33: 23.3 | AF33: 10.07 | AG33: 3.18 | AH33: 12 | AI33: 41
A34: 39427 | B34: Diciembre | C34: 6 | D34: Latifoliadas | E34: =crudos!E34+crudos!F34 -> 5 | F34: =crudos!G34+crudos!H34 -> 0 | G34: =crudos!I34+crudos!J34 -> 0 | L34: 8 | M34: 14 | N34: 3 | O34: 5 | P34: 14 | Q34: Jun | R34: 16 | S34: 2 | T34: 0 | U34: =SUM(R34:T34) -> 18 | V34: 0 | W34: =R34-V34 -> 16 | X34: =S34-V34 -> 2 | Y34: =T34-V34 -> 0 | Z34: =U34-V34 -> 18 | AB34: Feb | AC34: Toques 0-0,5m | AD34: 10 | AE34: 33.9 | AF34: 13.97 | AG34: 4.42 | AH34: 17 | AI34: 61
A35: 39427 | B35: Diciembre | C35: 6 | D35: Arbustos | E35: =crudos!E35+crudos!F35 -> 7 | F35: =crudos!G35+crudos!H35 -> 3 | G35: =crudos!I35+crudos!J35 -> 0 | L35: 9 | M35: 18 | N35: 0 | O35: 2 | P35: 1 | Q35: Ago | R35: 0 | S35: 2 | T35: 1 | U35: =SUM(R35:T35) -> 3 | V35: 2 | W35: =R35-V35 -> -2 | X35: =S35-V35 -> 0 | Y35: =T35-V35 -> -1 | Z35: =U35-V35 -> 1 | AB35: Feb | AC35: Toques 0,5-1m | AD35: 10 | AE35: 7.5 | AF35: 3.54 | AG35: 1.12 | AH35: 3 | AI35: 12
A36: 39427 | B36: Diciembre | C36: 6 | D36: Lianas / Enredaderas | E36: =crudos!E36+crudos!F36 -> 0 | F36: =crudos!G36+crudos!H36 -> 0 | G36: =crudos!I36+crudos!J36 -> 0 | L36: 10 | M36: 16 | N36: 2 | O36: 0 | P36: 0 | Q36: Ago | R36: 2 | S36: 5 | T36: 6 | U36: =SUM(R36:T36) -> 13 | V36: 2 | W36: =R36-V36 -> 0 | X36: =S36-V36 -> 3 | Y36: =T36-V36 -> 4 | Z36: =U36-V36 -> 11 | AB36: Feb | AC36: Toques 1-1,5m | AD36: 10 | AE36: 8.4 | AF36: 5.56 | AG36: 1.76 | AH36: 1 | AI36: 18
A37: 39427 | B37: Diciembre | C37: 6 | D37: Arboles | E37: =crudos!E37+crudos!F37 -> 0 | F37: =crudos!G37+crudos!H37 -> 0 | G37: =crudos!I37+crudos!J37 -> 0 | K37: Agosto | M37: 16 | N37: 27 | O37: 24 | P37: 19 | Q37: Ago | R37: 0 | S37: 0 | T37: 0 | U37: =SUM(R37:T37) -> 0 | V37: 7 | W37: =R37-V37 -> -7 | X37: =S37-V37 -> -7 | Y37: =T37-V37 -> -7 | Z37: =U37-V37 -> -7 | AB37: Feb | AC37: Toques totales | AD37: 10 | AE37: 49.8 | AF37: 15.24 | AG37: 4.82 | AH37: 25 | AI37: 79
A38: 39427 | B38: Diciembre | C38: 6 | D38: Helechos | E38: =crudos!E38+crudos!F38 -> 0 | F38: =crudos!G38+crudos!H38 -> 0 | G38: =crudos!I38+crudos!J38 -> 0 | L38: 1 | M38: 0 | N38: 2 | O38: 1 | P38: 2 | Q38: Ago | R38: 5 | S38: 1 | T38: 1 | U38: =SUM(R38:T38) -> 7 | V38: 0 | W38: =R38-V38 -> 5 | X38: =S38-V38 -> 1 | Y38: =T38-V38 -> 1 | Z38: =U38-V38 -> 7 | AB38: Feb | AC38: Quiebres nuevos | AD38: 10 | AE38: 0.1 | AF38: 0.32 | AG38: 0.1 | AH38: 0 | AI38: 1
A39: 39428 | B39: Diciembre | C39: 7 | D39: Gramineas | E39: =crudos!E39+crudos!F39 -> 3 | F39: =crudos!G39+crudos!H39 -> 0 | G39: =crudos!I39+crudos!J39 -> 0 | H39: 0 | L39: 2 | M39: 2 | N39: 5 | O39: 6 | P39: 2 | Q39: Ago | R39: 0 | S39: 3 | T39: 2 | U39: =SUM(R39:T39) -> 5 | V39: 0 | W39: =R39-V39 -> 0 | X39: =S39-V39 -> 3 | Y39: =T39-V39 -> 2 | Z39: =U39-V39 -> 5 | AB39: Feb | AC39: (0-0,5m)-Q | AD39: 10 | AE39: 33.8 | AF39: 13.83 | AG39: 4.37 | AH39: 17 | AI39: 61
A40: 39428 | B40: Diciembre | C40: 7 | D40: Latifoliadas | E40: =crudos!E40+crudos!F40 -> 4 | F40: =crudos!G40+crudos!H40 -> 0 | G40: =crudos!I40+crudos!J40 -> 0 | L40: 3 | M40: 0 | N40: 0 | O40: 0 | P40: 7 | Q40: Ago | R40: 0 | S40: 1 | T40: 0 | U40: =SUM(R40:T40) -> 1 | V40: 4 | W40: =R40-V40 -> -4 | X40: =S40-V40 -> -3 | Y40: =T40-V40 -> -4 | Z40: =U40-V40 -> -3 | AB40: Feb | AC40: (0,5-1m)-Q | AD40: 10 | AE40: 7.4 | AF40: 3.69 | AG40: 1.17 | AH40: 2 | AI40: 12
...

Sheet Análisis
A1: Medidas resumen | L1: Prueba de Kruskal Wallis | V1: Tabla resumen
X2: Frecuencia de quiebres recientes | Y2: Frecuencia de toques totales | Z2: D (0 - 0,5 m) | AA2: D (0,5 - 1 m) | AB2: D (1 - 1,5 m)
A3: Mes | B3: Variable | C3: n | D3: Media | E3: D.E. | F3: E.E. | G3: Mín | H3: Máx | V3: Meses | W3: n | X3: ẋ + de | Y3: ẋ + de | Z3: ẋ + de | AA3: ẋ + de | AB3: ẋ + de
A4: Abr | B4: Toques 0-0,5m | C4: 10 | D4: 25.3 | E4: 7.5 | F4: 2.37 | G4: 11 | H4: 37 | L4: Variable | M4: Mes | N4: N | O4: Medias | P4: D.E. | Q4: gl | R4: H | S4: p | V4: Febrero | W4: 10 | X4: 0,10 + 0,32 a | Y4: 49,80 + 15,24 d | Z4: 33,80 + 13,83 e | AA4: 7,40 + 3,69 b | AB4: 8,30 + 5,72 d
A5: Abr | B5: Toques 0,5-1m | C5: 10 | D5: 6.6 | E5: 5.42 | F5: 1.71 | G5: 0 | H5: 19 | L5: Toques 0-0,5m | M5: Abr | N5: 10 | O5: 25.3 | P5: 7.5 | Q5: 5 | R5: 45.49 | S5: <0,0001 | V5: Abril | W5: 10 | X5: 0,50 + 0,85 ab | Y5: 37,50 + 8,76 cd | Z5: 24,8 + 7,77 de | AA5: 6,10 + 5,47 b | AB5: 5,10 + 3,96 cd
A6: Abr | B6: Toques 1-1,5m | C6: 10 | D6: 5.6 | E6: 3.92 | F6: 1.24 | G6: 0 | H6: 12 | L6: Toques 0-0,5m | M6: Ago | N6: 10 | O6: 1.6 | P6: 2.07 | V6: Junio | W6: 10 | X6: 2,90 + 4,79 ab | Y6: 21,50 + 5,76 b | Z6: 12,50 + 5,38 bc | AA6: -0,20 + 4,71 a | AB6: 0,50 + 4,62 abc
A7: Abr | B7: Toques totales | C7: 10 | D7: 37.5 | E7: 8.76 | F7: 2.77 | G7: 25 | H7: 52 | L7: Toques 0-0,5m | M7: Dic | N7: 10 | O7: 16.5 | P7: 8.07 | V7: Agosto | W7: 10 | X7: 1,90 + 2,23 b | Y7: 6,70 + 4,79 a | Z7: -0,30 + 3,40 a | AA7: 0,80 + 3,74 a | AB7: 0,50 + 3,92 ab
A8: Abr | B8: Quiebres nuevos | C8: 10 | D8: 0.5 | E8: 0.85 | F8: 0.27 | G8: 0 | H8: 2 | L8: Toques 0-0,5m | M8: Feb | N8: 10 | O8: 33.9 | P8: 13.97 | V8: Octubre | W8: 10 | X8: 1,80 + 1,99 b | Y8: 10,00 + 6,78 a | Z8: 4,40 + 3,20 ab | AA8: 0,70 + 2,95 a | AB8: -0,50 + 2,07 a
A9: Abr | B9: (0-0,5m)-Q | C9: 10 | D9: 24.8 | E9: 7.77 | F9: 2.46 | G9: 11 | H9: 37 | L9: Toques 0-0,5m | M9: Jun | N9: 10 | O9: 15.4 | P9: 4.09 | V9: Diciembre | W9: 10 | X9: 0,20 + 0,42 a | Y9: 23,50 + 10,05 bc | Z9: 16,30 + 8,08 cd | AA9: 3,10 + 1,52 ab | AB9: 3,50 + 3,27 bcd
A10: Abr | B10: (0,5-1m)-Q | C10: 10 | D10: 6.1 | E10: 5.47 | F10: 1.73 | G10: -1 | H10: 19 | L10: Toques 0-0,5m | M10: Oct | N10: 10 | O10: 6.2 | P10: 4.26
A11: Abr | B11: (1-1,5m)-Q | C11: 10 | D11: 5.1 | E11: 3.96 | F11: 1.25 | G11: 0 | H11: 12
A12: Abr | B12: Totales-Q | C12: 10 | D12: 37 | E12: 8.96 | F12: 2.83 | G12: 24 | H12: 52 | L12: Trat. | M12: Ranks | V12: Meses | W12: Frecuencia de toques 0-0,5m | X12: Frecuencia de toques 0,5-1m | Y12: Frecuencia de toques 1-1,5m
A13: Ago | B13: Toques 0-0,5m | C13: 10 | D13: 1.6 | E13: 2.07 | F13: 0.65 | G13: 0 | H13: 5 | L13: Ago | M13: 7.15 | N13: A | V13: Febrero | W13: ẋ + de | X13: ẋ + de | Y13: ẋ + de
B14: Toques 0,5-1m | C14: 10 | D14: 2.7 | E14: 2.06 | F14: 0.65 | G14: 0 | H14: 7 | L14: Oct | M14: 15.8 | N14: A | V14: Abril | W14: 33,90 + 13,97 a | X14: 7,50 + 3,54 a | Y14: 8,40 + 5,56 ab
A15: Ago | B15: Toques 1-1,5m | C15: 10 | D15: 2.4 | E15: 2.37 | F15: 0.75 | G15: 0 | H15: 7 | L15: Jun | M15: 31.8 | O15: B | V15: Junio | W15: 25,30 + 7,50 c | X15: 6,60 + 5,42 c | Y15: 5,60 + 3,92 c
A16: Ago | B16: Toques totales | C16: 10 | D16: 6.7 | E16: 4.79 | F16: 1.51 | G16: 0 | H16: 14 | L16: Dic | M16: 32.45 | O16: B | V16: Agosto | W16: 15,40 + 4,09 a | X16: 2,70 + 2,11 a | Y16: 3,40 + 2,12 a
A17: Ago | B17: Quiebres nuevos | C17: 10 | D17: 1.9 | E17: 2.23 | F17: 0.71 | G17: 0 | H17: 7 | L17: Abr | M17: 45.15 | O17: B | P17: C | V17: Octubre | W17: 1,60 + 2,07 bc | X17: 2,70 + 2,06 bc | Y17: 2,40 + 2,37 bc
A18: Ago | B18: (0-0,5m)-Q | C18: 10 | D18: -0.3 | E18: 3.4 | F18: 1.08 | G18: -7 | H18: 5 | L18: Feb | M18: 50.65 | P18: C | V18: Diciembre | W18: 6,20 + 4,26 b | X18: 2,50 + 2,32 ab | Y18: 1,30 + 1,70 abc
A19: Ago | B19: (0,5-1m)-Q | C19: 10 | D19: 0.8 | E19: 3.74 | F19: 1.18 | G19: -7 | H19: 7 | L19: Medias con una letra común no son significativamente diferentes(p<= 0,05) | W19: 16,50 + 8,07 b | X19: 3,30 + 1,49 ab | Y19: 3,70 + 3,20 abc | Z19: Meses | AA19: Quiebres recientes | AB19: 0 - 0,5 m | AC19: 0,5 - 1 m | AD19: 1 - 1,5 m | AE19: Cobertura 0 - 1,5 m
A20: Ago | B20: (1-1,5m)-Q | C20: 10 | D20: 0.5 | E20: 3.92 | F20: 1.24 | G20: -7 | H20: 7 | Z20: Feb | AA20: 0.1 | AB20: 33.9 | AC20: 7.5 | AD20: 8.4 | AE20: 49.8
A21: Ago | B21: Totales-Q | C21: 10 | D21: 4.8 | E21: 6.3 | F21: 1.99 | G21: -7 | H21: 14 | Z21: Abr | AA21: 0.5 | AB21: 25.3 | AC21: 6.6 | AD21: 5.6 | AE21: 37.5
A22: Dic | B22: Toques 0-0,5m | C22: 10 | D22: 16.5 | E22: 8.07 | F22: 2.55 | G22: 5 | H22: 32 | Z22: Jun | AA22: 2.9 | AB22: 15.4 | AC22: 2.7 | AD22: 3.4 | AE22: 21.5
A23: Dic | B23: Toques 0,5-1m | C23: 10 | D23: 3.3 | E23: 1.49 | F23: 0.47 | G23: 1 | H23: 6 | L23: Variable | M23: Mes | N23: N | O23: Medias | P23: D.E. | Q23: gl | R23: H | S23: p | Z23: Ago | AA23: 1.9 | AB23: 1.6 | AC23: 2.7 | AD23: 2.4 | AE23: 6.7
A24: Dic | B24: Toques 1-1,5m | C24: 10 | D24: 3.7 | E24: 3.2 | F24: 1.01 | G24: 0 | H24: 11 | L24: Toques 0,5-1m | M24: Abr | N24: 10 | O24: 6.6 | P24: 5.42 | Q24: 5 | R24: 16.02 | S24: 0.006 | Z24: Oct | AA24: 1.8 | AB24: 6.2 | AC24: 2.5 | AD24: 1.3 | AE24: 10
A25: Dic | B25: Toques totales | C25: 10 | D25: 23.5 | E25: 10.05 | F25: 3.18 | G25: 12 | H25: 41 | L25: Toques 0,5-1m | M25: Ago | N25: 10 | O25: 2.7 | P25: 2.06 | Z25: Dic | AA25: 0.2 | AB25: 16.5 | AC25: 3.3 | AD25: 3.7 | AE25: 23.5
A26: Dic | B26: Quiebres nuevos | C26: 10 | D26: 0.2 | E26: 0.42 | F26: 0.13 | G26: 0 | H26: 1 | L26: Toques 0,5-1m | M26: Dic | N26: 10 | O26: 3.3 | P26: 1.49
A27: Dic | B27: (0-0,5m)-Q | C27: 10 | D27: 16.3 | E27: 8.08 | F27: 2.56 | G27: 5 | H27: 32 | L27: Toques 0,5-1m | M27: Feb | N27: 10 | O27: 7.5 | P27: 3.54
A28: Dic | B28: (0,5-1m)-Q | C28: 10 | D28: 3.1 | E28: 1.52 | F28: 0.48 | G28: 1 | H28: 6 | L28: Toques 0,5-1m | M28: Jun | N28: 10 | O28: 2.7 | P28: 2.11
A29: Dic | B29: (1-1,5m)-Q | C29: 10 | D29: 3.5 | E29: 3.27 | F29: 1.04 | G29: 0 | H29: 11 | L29: Toques 0,5-1m | M29: Oct | N29: 10 | O29: 2.5 | P29: 2.32 | Z29: (0-0,5m)-Q | AA29: (0,5-1m)-Q | AB29: (1-1,5m)-Q | AC29: Totales-Q
A30: Dic | B30: Totales-Q | C30: 10 | D30: 23.3 | E30: 10.07 | F30: 3.18 | G30: 12 | H30: 41 | Y30: Feb | Z30: 33.8 | AA30: 7.4 | AB30: 8.3 | AC30: 49.7
A31: Feb | B31: Toques 0-0,5m | C31: 10 | D31: 33.9 | E31: 13.97 | F31: 4.42 | G31: 17 | H31: 61 | L31: Trat. | M31: Ranks | Y31: Abr | Z31: 24.8 | AA31: 6.1 | AB31: 5.1 | AC31: 37
A32: Feb | B32: Toques 0,5-1m | C32: 10 | D32: 7.5 | E32: 3.54 | F32: 1.12 | G32: 3 | H32: 12 | L32: Oct | M32: 22.05 | N32: A | Y32: Jun | Z32: 12.5 | AA32: -0.2 | AB32: 0.5 | AC32: 18.6
A33: Feb | B33: Toques 1-1,5m | C33: 10 | D33: 8.4 | E33: 5.56 | F33: 1.76 | G33: 1 | H33: 18 | L33: Ago | M33: 22.65 | N33: A | Y33: Ago | Z33: -0.3 | AA33: 0.8 | AB33: 0.5 | AC33: 4.8
A34: Feb | B34: Toques totales | C34: 10 | D34: 49.8 | E34: 15.24 | F34: 4.82 | G34: 25 | H34: 79 | L34: Jun | M34: 24.45 | N34: A | O34: B | Y34: Oct | Z34: 4.4 | AA34: 0.7 | AB34: -0.5 | AC34: 8.2
A35: Feb | B35: Quiebres nuevos | C35: 10 | D35: 0.1 | E35: 0.32 | F35: 0.1 | G35: 0 | H35: 1 | L35: Dic | M35: 28.8 | N35: A | O35: B | Y35: Dic | Z35: 16.3 | AA35: 3.1 | AB35: 3.5 | AC35: 23.3
A36: Feb | B36: (0-0,5m)-Q | C36: 10 | D36: 33.8 | E36: 13.83 | F36: 4.37 | G36: 17 | H36: 61 | L36: Abr | M36: 38.85 | O36: B | P36: C
A37: Feb | B37: (0,5-1m)-Q | C37: 10 | D37: 7.4 | E37: 3.69 | F37: 1.17 | G37: 2 | H37: 12 | L37: Feb | M37: 46.2 | P37: C
A38: Feb | B38: (1-1,5m)-Q | C38: 10 | D38: 8.3 | E38: 5.72 | F38: 1.81 | G38: 0 | H38: 18 | L38: Medias con una letra común no son significativamente diferentes(p<= 0,05)
A39: Feb | B39: Totales-Q | C39: 10 | D39: 49.7 | E39: 15.2 | F39: 4.81 | G39: 25 | H39: 79
A40: Jun | B40: Toques 0-0,5m | C40: 10 | D40: 15.4 | E40: 4.09 | F40: 1.29 | G40: 9 | H40: 21
...

Sheet Factorial_INFOSTAT
A1: Mes | B1: Cobertura - Quiebres | C1: Diferencias
A2: Feb | B2: 0-0,5m-Quiebres | C2: 35 | E2: Análisis de la varianza FACTORIAL
A3: Feb | B3: 0-0,5m-Quiebres | C3: 51
A4: Feb | B4: 0-0,5m-Quiebres | C4: 32 | E4: Variable | F4: N | G4: R² | H4: R² Aj | I4: CV
A5: Feb | B5: 0-0,5m-Quiebres | C5: 27 | E5: Diferencias | F5: 180 | G5: 0.75 | H5: 0.72 | I5: 79.08
A6: Feb | B6: 0-0,5m-Quiebres | C6: 61
A7: Feb | B7: 0-0,5m-Quiebres | C7: 20 | E7: Cuadro de Análisis de la Varianza (SC tipo III)
A8: Feb | B8: 0-0,5m-Quiebres | C8: 30 | E8: F.V. | F8: SC | G8: gl | H8: CM | I8: F | J8: p-valor
A9: Feb | B9: 0-0,5m-Quiebres | C9: 41 | E9: Modelo. | F9: 15162.84 | G9: 17 | H9: 891.93 | I9: 28.74 | J9: <0,0001
A10: Feb | B10: 0-0,5m-Quiebres | C10: 17 | E10: Meses | F10: 5923.18 | G10: 5 | H10: 1184.64 | I10: 38.18 | J10: <0,0001
A11: Feb | B11: 0-0,5m-Quiebres | C11: 24 | E11: Cobertura - Quiebres | F11: 6060.01 | G11: 2 | H11: 3030.01 | I11: 97.65 | J11: <0,0001
A12: Feb | B12: 0,5-1m-Quiebres | C12: 10 | E12: Meses*Cobertura | F12: 3179.66 | G12: 10 | H12: 317.97 | I12: 10.25 | J12: <0,0001
A13: Feb | B13: 0,5-1m-Quiebres | C13: 2 | E13: Error | F13: 5026.8 | G13: 162 | H13: 31.03
A14: Feb | B14: 0,5-1m-Quiebres | C14: 11 | E14: Total | F14: 20189.64 | G14: 179
A15: Feb | B15: 0,5-1m-Quiebres | C15: 7
A16: Feb | B16: 0,5-1m-Quiebres | C16: 3 | E16: Test:Tukey Alfa=0,05 DMS=4,10664
A17: Feb | B17: 0,5-1m-Quiebres | C17: 4 | E17: Error: 31,0296 gl: 162
A18: Feb | B18: 0,5-1m-Quiebres | C18: 12 | E18: Meses | F18: Medias | G18: n | H18: E.E.
A19: Feb | B19: 0,5-1m-Quiebres | C19: 9 | E19: Ago | F19: 0.33 | G19: 30 | H19: 1.02 | I19: A
A20: Feb | B20: 0,5-1m-Quiebres | C20: 5 | E20: Oct | F20: 1.53 | G20: 30 | H20: 1.02 | I20: A
A21: Feb | B21: 0,5-1m-Quiebres | C21: 11 | E21: Jun | F21: 4.27 | G21: 30 | H21: 1.02 | I21: A | J21: B
A22: Feb | B22: 1-1,5m-Quiebres | C22: 11 | E22: Dic | F22: 7.63 | G22: 30 | H22: 1.02 | J22: B
A23: Feb | B23: 1-1,5m-Quiebres | C23: 0 | E23: Abr | F23: 12 | G23: 30 | H23: 1.02 | K23: C
A24: Feb | B24: 1-1,5m-Quiebres | C24: 4 | E24: Feb | F24: 16.5 | G24: 30 | H24: 1.02 | L24: D
A25: Feb | B25: 1-1,5m-Quiebres | C25: 8 | E25: Medias con una letra común no son significativamente diferentes(p<= 0,05)
A26: Feb | B26: 1-1,5m-Quiebres | C26: 15
A27: Feb | B27: 1-1,5m-Quiebres | C27: 12
A28: Feb | B28: 1-1,5m-Quiebres | C28: 18 | E28: Test:Tukey Alfa=0,05 DMS=2,38714
A29: Feb | B29: 1-1,5m-Quiebres | C29: 8 | E29: Error: 31,0296 gl: 162
A30: Feb | B30: 1-1,5m-Quiebres | C30: 3 | E30: Cobertura - Quiebres | F30: Medias | G30: n | H30: E.E.
A31: Feb | B31: 1-1,5m-Quiebres | C31: 4 | E31: 1-1,5m-Quiebres | F31: 2.9 | G31: 60 | H31: 0.72 | I31: A
A32: Feb | B32: Toques totales-Quiebres | C32: 56 | E32: 0,5-1m-Quiebres | F32: 2.98 | G32: 60 | H32: 0.72 | I32: A
A33: Feb | B33: Toques totales-Quiebres | C33: 55 | E33: 0-0,5m-Quiebres | F33: 15.25 | G33: 60 | H33: 0.72 | J33: B
A34: Feb | B34: Toques totales-Quiebres | C34: 47 | E34: Medias con una letra común no son significativamente diferentes(p<= 0,05)
A35: Feb | B35: Toques totales-Quiebres | C35: 42
A36: Feb | B36: Toques totales-Quiebres | C36: 79
A37: Feb | B37: Toques totales-Quiebres | C37: 36 | E37: Test:Tukey Alfa=0,05 DMS=8,71399
A38: Feb | B38: Toques totales-Quiebres | C38: 60 | E38: Error: 31,0296 gl: 162 | S38: Alturas de la vegetación
A39: Feb | B39: Toques totales-Quiebres | C39: 58 | E39: Meses | F39: Cobertura - Quiebres | G39: Medias | H39: n | I39: E.E. | S39: 0 - 0,5 m | T39: 0,5 - 1 m | U39: 1 - 1,5 m
A40: Feb | B40: Toques totales-Quiebres | C40: 25 | E40: Oct | F40: 1-1,5m-Quiebres | G40: -0.5 | H40: 10 | I40: 1.76 | J40: A | Q40: Meses | R40: Medias | S40: 15,25 b | T40: 2,98 a | U40: 2,90 a
...
